Workbook

Sheet About
A1: BLP BAU LCFS Percentage | B1: Kansas | C1: 46190 | E1: State | F1: State
B2: =LOOKUP(B1,E2:F51,F2:F51) -> KS | E2: Alabama | F2: AL
A3: Source: | B3: California Air Resource Board | E3: Alaska | F3: AK
B4: CARB | E4: Arizona | F4: AZ
B5: https://ww2.arb.ca.gov/sites/default/files/2025-11/LCFS%20Basics_post11-20-25_final.pdf | E5: Arkansas | F5: AR
B6: Overview of the Low Carbon Fuel Standard | E6: California | F6: CA
B7: 2025 | E7: Colorado | F7: CO
E8: Connecticut | F8: CT
E9: Delaware | F9: DE
B10: Washington Department of Ecology | E10: Florida | F10: FL
B11: Clean Fuel Standard | E11: Georgia | F11: GA
B12: https://ecology.wa.gov/air-climate/reducing-greenhouse-gas-emissions/clean-fuel-standard | E12: Hawaii | F12: HI
B13: "The Clean Fuel Standard law requires fuel suppliers to gradually reduce the carbon intensity of transportation fuels to 20% below 2017 levels by 2034." | E13: Idaho | F13: ID
E14: Illinois | F14: IL
E15: Indiana | F15: IN
B16: Oregon Clean Fuels Program | E16: Iowa | F16: IA
B17: Clean Fuels Program | E17: Kansas | F17: KS
B18: https://www.oregon.gov/deq/ghgp/cfp/Pages/CFP-Overview.aspx | E18: Kentucky | F18: KY
B19: 2026 | E19: Louisiana | F19: LA
E20: Maine | F20: ME
B21: New Mexico | E21: Maryland | F21: MD
B22: https://data.usclimatealliance.org/policy/2453 | E22: Massachusetts | F22: MA
E23: Michigan | F23: MI
E24: Minnesota | F24: MN
E25: Mississippi | F25: MS
A26: Notes | E26: Missouri | F26: MO
E27: Montana | F27: MT
A28: hold constant | E28: Nebraska | F28: NE
E29: Nevada | F29: NV
E30: New Hampshire | F30: NH
E31: New Jersey | F31: NJ
E32: New Mexico | F32: NM
E33: New York | F33: NY
E34: North Carolina | F34: NC
E35: North Dakota | F35: ND
E36: Ohio | F36: OH
E37: Oklahoma | F37: OK
E38: Oregon | F38: OR
E39: Pennsylvania | F39: PA
E40: Rhode Island | F40: RI
...

Sheet StatePolicies
A1: California Calcs
G2: State | H2: State | I2: LCFS | J2: 2024 | K2: 2025 | L2: 2026 | M2: 2027 | N2: 2028 | O2: 2029 | P2: 2030 | Q2: 2031 | R2: 2032 | S2: 2033 | T2: 2034 | U2: 2035 | V2: 2036 | W2: 2037 | X2: 2038 | Y2: 2039 | Z2: 2040 | AA2: 2041 | AB2: 2042 | AC2: 2043 | AD2: 2044 | AE2: 2045 | AF2: 2046 | AG2: 2047 | AH2: 2048 | AI2: 2049 | AJ2: 2050
A3: Goal | B3: 30% reduction by 2030, 90% by 2045 | G3: Alabama | H3: AL | I3: No | J3: 0 | K3: 0 | L3: 0 | M3: 0 | N3: 0 | O3: 0 | P3: 0 | Q3: 0 | R3: 0 | S3: 0 | T3: 0 | U3: 0 | V3: 0 | W3: 0 | X3: 0 | Y3: 0 | Z3: 0 | AA3: 0 | AB3: 0 | AC3: 0 | AD3: 0 | AE3: 0 | AF3: 0 | AG3: 0 | AH3: 0 | AI3: 0 | AJ3: 0
B4: 2020 | C4: 2030 | D4: 2045 | G4: Alaska | H4: AK | I4: No | J4: 0 | K4: 0 | L4: 0 | M4: 0 | N4: 0 | O4: 0 | P4: 0 | Q4: 0 | R4: 0 | S4: 0 | T4: 0 | U4: 0 | V4: 0 | W4: 0 | X4: 0 | Y4: 0 | Z4: 0 | AA4: 0 | AB4: 0 | AC4: 0 | AD4: 0 | AE4: 0 | AF4: 0 | AG4: 0 | AH4: 0 | AI4: 0 | AJ4: 0
A5: reduction | B5: 0.1 | C5: 0.3 | D5: 0.9 | G5: Arizona | H5: AZ | I5: No | J5: 0 | K5: 0 | L5: 0 | M5: 0 | N5: 0 | O5: 0 | P5: 0 | Q5: 0 | R5: 0 | S5: 0 | T5: 0 | U5: 0 | V5: 0 | W5: 0 | X5: 0 | Y5: 0 | Z5: 0 | AA5: 0 | AB5: 0 | AC5: 0 | AD5: 0 | AE5: 0 | AF5: 0 | AG5: 0 | AH5: 0 | AI5: 0 | AJ5: 0
G6: Arkansas | H6: AR | I6: No | J6: 0 | K6: 0 | L6: 0 | M6: 0 | N6: 0 | O6: 0 | P6: 0 | Q6: 0 | R6: 0 | S6: 0 | T6: 0 | U6: 0 | V6: 0 | W6: 0 | X6: 0 | Y6: 0 | Z6: 0 | AA6: 0 | AB6: 0 | AC6: 0 | AD6: 0 | AE6: 0 | AF6: 0 | AG6: 0 | AH6: 0 | AI6: 0 | AJ6: 0
G7: California | H7: CA | I7: Yes | J7: =_xlfn.FORECAST.ETS(J2,$B$5:$C$5,$B$4:$C$4) -> 0.18 | K7: =_xlfn.FORECAST.ETS(K2,$B$5:$C$5,$B$4:$C$4) -> 0.2 | L7: =_xlfn.FORECAST.ETS(L2,$B$5:$C$5,$B$4:$C$4) -> 0.22 | M7: =_xlfn.FORECAST.ETS(M2,$B$5:$C$5,$B$4:$C$4) -> 0.24 | N7: =_xlfn.FORECAST.ETS(N2,$B$5:$C$5,$B$4:$C$4) -> 0.26 | O7: =_xlfn.FORECAST.ETS(O2,$B$5:$C$5,$B$4:$C$4) -> 0.28 | P7: =_xlfn.FORECAST.ETS(P2,$B$5:$C$5,$B$4:$C$4) -> 0.3 | Q7: =_xlfn.FORECAST.ETS(Q2,$C$5:$D$5,$C$4:$D$4) -> 0.34 | R7: =_xlfn.FORECAST.ETS(R2,$C$5:$D$5,$C$4:$D$4) -> 0.38 | S7: =_xlfn.FORECAST.ETS(S2,$C$5:$D$5,$C$4:$D$4) -> 0.42 | T7: =_xlfn.FORECAST.ETS(T2,$C$5:$D$5,$C$4:$D$4) -> 0.46 | U7: =_xlfn.FORECAST.ETS(U2,$C$5:$D$5,$C$4:$D$4) -> 0.5 | V7: =_xlfn.FORECAST.ETS(V2,$C$5:$D$5,$C$4:$D$4) -> 0.54 | W7: =_xlfn.FORECAST.ETS(W2,$C$5:$D$5,$C$4:$D$4) -> 0.58 | X7: =_xlfn.FORECAST.ETS(X2,$C$5:$D$5,$C$4:$D$4) -> 0.62 | ... AE7: =_xlfn.FORECAST.ETS(AE2,$C$5:$D$5,$C$4:$D$4) -> 0.9 | AF7: =AE7 -> 0.9 | AG7: =AF7 -> 0.9 | AH7: =AG7 -> 0.9 | AI7: =AH7 -> 0.9 | AJ7: =AI7 -> 0.9
G8: Colorado | H8: CO | I8: No | J8: 0 | K8: 0 | L8: 0 | M8: 0 | N8: 0 | O8: 0 | P8: 0 | Q8: 0 | R8: 0 | S8: 0 | T8: 0 | U8: 0 | V8: 0 | W8: 0 | X8: 0 | Y8: 0 | Z8: 0 | AA8: 0 | AB8: 0 | AC8: 0 | AD8: 0 | AE8: 0 | AF8: 0 | AG8: 0 | AH8: 0 | AI8: 0 | AJ8: 0
G9: Connecticut | H9: CT | I9: No | J9: 0 | K9: 0 | L9: 0 | M9: 0 | N9: 0 | O9: 0 | P9: 0 | Q9: 0 | R9: 0 | S9: 0 | T9: 0 | U9: 0 | V9: 0 | W9: 0 | X9: 0 | Y9: 0 | Z9: 0 | AA9: 0 | AB9: 0 | AC9: 0 | AD9: 0 | AE9: 0 | AF9: 0 | AG9: 0 | AH9: 0 | AI9: 0 | AJ9: 0
G10: Delaware | H10: DE | I10: No | J10: 0 | K10: 0 | L10: 0 | M10: 0 | N10: 0 | O10: 0 | P10: 0 | Q10: 0 | R10: 0 | S10: 0 | T10: 0 | U10: 0 | V10: 0 | W10: 0 | X10: 0 | Y10: 0 | Z10: 0 | AA10: 0 | AB10: 0 | AC10: 0 | AD10: 0 | AE10: 0 | AF10: 0 | AG10: 0 | AH10: 0 | AI10: 0 | AJ10: 0
G11: Florida | H11: FL | I11: No | J11: 0 | K11: 0 | L11: 0 | M11: 0 | N11: 0 | O11: 0 | P11: 0 | Q11: 0 | R11: 0 | S11: 0 | T11: 0 | U11: 0 | V11: 0 | W11: 0 | X11: 0 | Y11: 0 | Z11: 0 | AA11: 0 | AB11: 0 | AC11: 0 | AD11: 0 | AE11: 0 | AF11: 0 | AG11: 0 | AH11: 0 | AI11: 0 | AJ11: 0
G12: Georgia | H12: GA | I12: No | J12: 0 | K12: 0 | L12: 0 | M12: 0 | N12: 0 | O12: 0 | P12: 0 | Q12: 0 | R12: 0 | S12: 0 | T12: 0 | U12: 0 | V12: 0 | W12: 0 | X12: 0 | Y12: 0 | Z12: 0 | AA12: 0 | AB12: 0 | AC12: 0 | AD12: 0 | AE12: 0 | AF12: 0 | AG12: 0 | AH12: 0 | AI12: 0 | AJ12: 0
G13: Hawaii | H13: HI | I13: No | J13: 0 | K13: 0 | L13: 0 | M13: 0 | N13: 0 | O13: 0 | P13: 0 | Q13: 0 | R13: 0 | S13: 0 | T13: 0 | U13: 0 | V13: 0 | W13: 0 | X13: 0 | Y13: 0 | Z13: 0 | AA13: 0 | AB13: 0 | AC13: 0 | AD13: 0 | AE13: 0 | AF13: 0 | AG13: 0 | AH13: 0 | AI13: 0 | AJ13: 0
G14: Idaho | H14: ID | I14: No | J14: 0 | K14: 0 | L14: 0 | M14: 0 | N14: 0 | O14: 0 | P14: 0 | Q14: 0 | R14: 0 | S14: 0 | T14: 0 | U14: 0 | V14: 0 | W14: 0 | X14: 0 | Y14: 0 | Z14: 0 | AA14: 0 | AB14: 0 | AC14: 0 | AD14: 0 | AE14: 0 | AF14: 0 | AG14: 0 | AH14: 0 | AI14: 0 | AJ14: 0
G15: Illinois | H15: IL | I15: No | J15: 0 | K15: 0 | L15: 0 | M15: 0 | N15: 0 | O15: 0 | P15: 0 | Q15: 0 | R15: 0 | S15: 0 | T15: 0 | U15: 0 | V15: 0 | W15: 0 | X15: 0 | Y15: 0 | Z15: 0 | AA15: 0 | AB15: 0 | AC15: 0 | AD15: 0 | AE15: 0 | AF15: 0 | AG15: 0 | AH15: 0 | AI15: 0 | AJ15: 0
G16: Indiana | H16: IN | I16: No | J16: 0 | K16: 0 | L16: 0 | M16: 0 | N16: 0 | O16: 0 | P16: 0 | Q16: 0 | R16: 0 | S16: 0 | T16: 0 | U16: 0 | V16: 0 | W16: 0 | X16: 0 | Y16: 0 | Z16: 0 | AA16: 0 | AB16: 0 | AC16: 0 | AD16: 0 | AE16: 0 | AF16: 0 | AG16: 0 | AH16: 0 | AI16: 0 | AJ16: 0
G17: Iowa | H17: IA | I17: No | J17: 0 | K17: 0 | L17: 0 | M17: 0 | N17: 0 | O17: 0 | P17: 0 | Q17: 0 | R17: 0 | S17: 0 | T17: 0 | U17: 0 | V17: 0 | W17: 0 | X17: 0 | Y17: 0 | Z17: 0 | AA17: 0 | AB17: 0 | AC17: 0 | AD17: 0 | AE17: 0 | AF17: 0 | AG17: 0 | AH17: 0 | AI17: 0 | AJ17: 0
G18: Kansas | H18: KS | I18: No | J18: 0 | K18: 0 | L18: 0 | M18: 0 | N18: 0 | O18: 0 | P18: 0 | Q18: 0 | R18: 0 | S18: 0 | T18: 0 | U18: 0 | V18: 0 | W18: 0 | X18: 0 | Y18: 0 | Z18: 0 | AA18: 0 | AB18: 0 | AC18: 0 | AD18: 0 | AE18: 0 | AF18: 0 | AG18: 0 | AH18: 0 | AI18: 0 | AJ18: 0
G19: Kentucky | H19: KY | I19: No | J19: 0 | K19: 0 | L19: 0 | M19: 0 | N19: 0 | O19: 0 | P19: 0 | Q19: 0 | R19: 0 | S19: 0 | T19: 0 | U19: 0 | V19: 0 | W19: 0 | X19: 0 | Y19: 0 | Z19: 0 | AA19: 0 | AB19: 0 | AC19: 0 | AD19: 0 | AE19: 0 | AF19: 0 | AG19: 0 | AH19: 0 | AI19: 0 | AJ19: 0
... G26: Mississippi | H26: MS | I26: No | J26: 0 | K26: 0 | L26: 0 | M26: 0 | N26: 0 | O26: 0 | P26: 0 | Q26: 0 | R26: 0 | S26: 0 | T26: 0 | U26: 0 | V26: 0 | W26: 0 | X26: 0 | Y26: 0 | Z26: 0 | AA26: 0 | AB26: 0 | AC26: 0 | AD26: 0 | AE26: 0 | AF26: 0 | AG26: 0 | AH26: 0 | AI26: 0 | AJ26: 0
A27: Washington Calcs | G27: Missouri | H27: MO | I27: No | J27: 0 | K27: 0 | L27: 0 | M27: 0 | N27: 0 | O27: 0 | P27: 0 | Q27: 0 | R27: 0 | S27: 0 | T27: 0 | U27: 0 | V27: 0 | W27: 0 | X27: 0 | Y27: 0 | Z27: 0 | AA27: 0 | AB27: 0 | AC27: 0 | AD27: 0 | AE27: 0 | AF27: 0 | AG27: 0 | AH27: 0 | AI27: 0 | AJ27: 0
G28: Montana | H28: MT | I28: No | J28: 0 | K28: 0 | L28: 0 | M28: 0 | N28: 0 | O28: 0 | P28: 0 | Q28: 0 | R28: 0 | S28: 0 | T28: 0 | U28: 0 | V28: 0 | W28: 0 | X28: 0 | Y28: 0 | Z28: 0 | AA28: 0 | AB28: 0 | AC28: 0 | AD28: 0 | AE28: 0 | AF28: 0 | AG28: 0 | AH28: 0 | AI28: 0 | AJ28: 0
A29: 2025 | B29: 2026 | C29: 2027 | D29: 2038 | G29: Nebraska | H29: NE | I29: No | J29: 0 | K29: 0 | L29: 0 | M29: 0 | N29: 0 | O29: 0 | P29: 0 | Q29: 0 | R29: 0 | S29: 0 | T29: 0 | U29: 0 | V29: 0 | W29: 0 | X29: 0 | Y29: 0 | Z29: 0 | AA29: 0 | AB29: 0 | AC29: 0 | AD29: 0 | AE29: 0 | AF29: 0 | AG29: 0 | AH29: 0 | AI29: 0 | AJ29: 0
A30: 0.02 | B30: 0.07 | C30: 0.11 | D30: 0.45 | G30: Nevada | H30: NV | I30: No | J30: 0 | K30: 0 | L30: 0 | M30: 0 | N30: 0 | O30: 0 | P30: 0 | Q30: 0 | R30: 0 | S30: 0 | T30: 0 | U30: 0 | V30: 0 | W30: 0 | X30: 0 | Y30: 0 | Z30: 0 | AA30: 0 | AB30: 0 | AC30: 0 | AD30: 0 | AE30: 0 | AF30: 0 | AG30: 0 | AH30: 0 | AI30: 0 | AJ30: 0
G31: New Hampshire | H31: NH | I31: No | J31: 0 | K31: 0 | L31: 0 | M31: 0 | N31: 0 | O31: 0 | P31: 0 | Q31: 0 | R31: 0 | S31: 0 | T31: 0 | U31: 0 | V31: 0 | W31: 0 | X31: 0 | Y31: 0 | Z31: 0 | AA31: 0 | AB31: 0 | AC31: 0 | AD31: 0 | AE31: 0 | AF31: 0 | AG31: 0 | AH31: 0 | AI31: 0 | AJ31: 0
G32: New Jersey | H32: NJ | I32: No | J32: 0 | K32: 0 | L32: 0 | M32: 0 | N32: 0 | O32: 0 | P32: 0 | Q32: 0 | R32: 0 | S32: 0 | T32: 0 | U32: 0 | V32: 0 | W32: 0 | X32: 0 | Y32: 0 | Z32: 0 | AA32: 0 | AB32: 0 | AC32: 0 | AD32: 0 | AE32: 0 | AF32: 0 | AG32: 0 | AH32: 0 | AI32: 0 | AJ32: 0
G33: New Mexico | H33: NM | I33: No | J33: =_xlfn.FORECAST.ETS(J2,$A$56:$B$56,$A$55:$B$55) -> 0.086 | K33: =_xlfn.FORECAST.ETS(K2,$A$56:$B$56,$A$55:$B$55) -> 0.105 | L33: =_xlfn.FORECAST.ETS(L2,$A$56:$B$56,$A$55:$B$55) -> 0.124 | M33: =_xlfn.FORECAST.ETS(M2,$A$56:$B$56,$A$55:$B$55) -> 0.143 | N33: =_xlfn.FORECAST.ETS(N2,$A$56:$B$56,$A$55:$B$55) -> 0.162 | O33: =_xlfn.FORECAST.ETS(O2,$A$56:$B$56,$A$55:$B$55) -> 0.181 | P33: =_xlfn.FORECAST.ETS(P2,$A$56:$B$56,$A$55:$B$55) -> 0.2 | Q33: =_xlfn.FORECAST.ETS(Q2,$B$56:$C$56,$B$55:$C$55) -> 0.21 | R33: =_xlfn.FORECAST.ETS(R2,$B$56:$C$56,$B$55:$C$55) -> 0.22 | S33: =_xlfn.FORECAST.ETS(S2,$B$56:$C$56,$B$55:$C$55) -> 0.23 | T33: =_xlfn.FORECAST.ETS(T2,$B$56:$C$56,$B$55:$C$55) -> 0.24 | U33: =_xlfn.FORECAST.ETS(U2,$B$56:$C$56,$B$55:$C$55) -> 0.25 | V33: =_xlfn.FORECAST.ETS(V2,$B$56:$C$56,$B$55:$C$55) -> 0.26 | W33: =_xlfn.FORECAST.ETS(W2,$B$56:$C$56,$B$55:$C$55) -> 0.27 | X33: =_xlfn.FORECAST.ETS(X2,$B$56:$C$56,$B$55:$C$55) -> 0.28 | ... Z33: =_xlfn.FORECAST.ETS(Z2,$B$56:$C$56,$B$55:$C$55) -> 0.3 | AA33: =Z33 -> 0.3 | AB33: =AA33 -> 0.3 | AC33: =AB33 -> 0.3 | AD33: =AC33 -> 0.3 | AE33: =AD33 -> 0.3 | AF33: =AE33 -> 0.3 | AG33: =AF33 -> 0.3 | AH33: =AG33 -> 0.3 | ... AJ33: =AI33 -> 0.3
G34: New York | H34: NY | I34: No | J34: 0 | K34: 0 | L34: 0 | M34: 0 | N34: 0 | O34: 0 | P34: 0 | Q34: 0 | R34: 0 | S34: 0 | T34: 0 | U34: 0 | V34: 0 | W34: 0 | X34: 0 | Y34: 0 | Z34: 0 | AA34: 0 | AB34: 0 | AC34: 0 | AD34: 0 | AE34: 0 | AF34: 0 | AG34: 0 | AH34: 0 | AI34: 0 | AJ34: 0
G35: North Carolina | H35: NC | I35: No | J35: 0 | K35: 0 | L35: 0 | M35: 0 | N35: 0 | O35: 0 | P35: 0 | Q35: 0 | R35: 0 | S35: 0 | T35: 0 | U35: 0 | V35: 0 | W35: 0 | X35: 0 | Y35: 0 | Z35: 0 | AA35: 0 | AB35: 0 | AC35: 0 | AD35: 0 | AE35: 0 | AF35: 0 | AG35: 0 | AH35: 0 | AI35: 0 | AJ35: 0
G36: North Dakota | H36: ND | I36: No | J36: 0 | K36: 0 | L36: 0 | M36: 0 | N36: 0 | O36: 0 | P36: 0 | Q36: 0 | R36: 0 | S36: 0 | T36: 0 | U36: 0 | V36: 0 | W36: 0 | X36: 0 | Y36: 0 | Z36: 0 | AA36: 0 | AB36: 0 | AC36: 0 | AD36: 0 | AE36: 0 | AF36: 0 | AG36: 0 | AH36: 0 | AI36: 0 | AJ36: 0
G37: Ohio | H37: OH | I37: No | J37: 0 | K37: 0 | L37: 0 | M37: 0 | N37: 0 | O37: 0 | P37: 0 | Q37: 0 | R37: 0 | S37: 0 | T37: 0 | U37: 0 | V37: 0 | W37: 0 | X37: 0 | Y37: 0 | Z37: 0 | AA37: 0 | AB37: 0 | AC37: 0 | AD37: 0 | AE37: 0 | AF37: 0 | AG37: 0 | AH37: 0 | AI37: 0 | AJ37: 0
G38: Oklahoma | H38: OK | I38: No | J38: 0 | K38: 0 | L38: 0 | M38: 0 | N38: 0 | O38: 0 | P38: 0 | Q38: 0 | R38: 0 | S38: 0 | T38: 0 | U38: 0 | V38: 0 | W38: 0 | X38: 0 | Y38: 0 | Z38: 0 | AA38: 0 | AB38: 0 | AC38: 0 | AD38: 0 | AE38: 0 | AF38: 0 | AG38: 0 | AH38: 0 | AI38: 0 | AJ38: 0
G39: Oregon | H39: OR | I39: Yes | J39: =_xlfn.FORECAST.ETS(J2,$A$49:$B$49,$A$48:$B$48) -> 0.11 | K39: =_xlfn.FORECAST.ETS(K2,$A$49:$B$49,$A$48:$B$48) -> 0.125 | L39: =_xlfn.FORECAST.ETS(L2,$A$49:$B$49,$A$48:$B$48) -> 0.14 | M39: =_xlfn.FORECAST.ETS(M2,$A$49:$B$49,$A$48:$B$48) -> 0.155 | N39: =_xlfn.FORECAST.ETS(N2,$A$49:$B$49,$A$48:$B$48) -> 0.17 | O39: =_xlfn.FORECAST.ETS(O2,$A$49:$B$49,$A$48:$B$48) -> 0.185 | P39: =_xlfn.FORECAST.ETS(P2,$A$49:$B$49,$A$48:$B$48) -> 0.2 | Q39: =_xlfn.FORECAST.ETS(Q2,$B$49:$C$49,$B$48:$C$48) -> 0.234 | R39: =_xlfn.FORECAST.ETS(R2,$B$49:$C$49,$B$48:$C$48) -> 0.268 | S39: =_xlfn.FORECAST.ETS(S2,$B$49:$C$49,$B$48:$C$48) -> 0.302 | T39: =_xlfn.FORECAST.ETS(T2,$B$49:$C$49,$B$48:$C$48) -> 0.336 | U39: =_xlfn.FORECAST.ETS(U2,$B$49:$C$49,$B$48:$C$48) -> 0.37 | V39: =U39 -> 0.37 | W39: =V39 -> 0.37 | X39: =W39 -> 0.37 | Y39: =X39 -> 0.37 | Z39: =Y39 -> 0.37 | AA39: =Z39 -> 0.37 | AB39: =AA39 -> 0.37 | AC39: =AB39 -> 0.37 | ... AJ39: =AI39 -> 0.37
G40: Pennsylvania | H40: PA | I40: No | J40: 0 | K40: 0 | L40: 0 | M40: 0 | N40: 0 | O40: 0 | P40: 0 | Q40: 0 | R40: 0 | S40: 0 | T40: 0 | U40: 0 | V40: 0 | W40: 0 | X40: 0 | Y40: 0 | Z40: 0 | AA40: 0 | AB40: 0 | AC40: 0 | AD40: 0 | AE40: 0 | AF40: 0 | AG40: 0 | AH40: 0 | AI40: 0 | AJ40: 0
G41: Rhode Island | H41: RI | I41: No | J41: 0 | K41: 0 | L41: 0 | M41: 0 | N41: 0 | O41: 0 | P41: 0 | Q41: 0 | R41: 0 | S41: 0 | T41: 0 | U41: 0 | V41: 0 | W41: 0 | X41: 0 | Y41: 0 | Z41: 0 | AA41: 0 | AB41: 0 | AC41: 0 | AD41: 0 | AE41: 0 | AF41: 0 | AG41: 0 | AH41: 0 | AI41: 0 | AJ41: 0
G42: South Carolina | H42: SC | I42: No | J42: 0 | K42: 0 | L42: 0 | M42: 0 | N42: 0 | O42: 0 | P42: 0 | Q42: 0 | R42: 0 | S42: 0 | T42: 0 | U42: 0 | V42: 0 | W42: 0 | X42: 0 | Y42: 0 | Z42: 0 | AA42: 0 | AB42: 0 | AC42: 0 | AD42: 0 | AE42: 0 | AF42: 0 | AG42: 0 | AH42: 0 | AI42: 0 | AJ42: 0
G43: South Dakota | H43: SD | I43: No | J43: 0 | K43: 0 | L43: 0 | M43: 0 | N43: 0 | O43: 0 | P43: 0 | Q43: 0 | R43: 0 | S43: 0 | T43: 0 | U43: 0 | V43: 0 | W43: 0 | X43: 0 | Y43: 0 | Z43: 0 | AA43: 0 | AB43: 0 | AC43: 0 | AD43: 0 | AE43: 0 | AF43: 0 | AG43: 0 | AH43: 0 | AI43: 0 | AJ43: 0
G44: Tennessee | H44: TN | I44: No | J44: 0 | K44: 0 | L44: 0 | M44: 0 | N44: 0 | O44: 0 | P44: 0 | Q44: 0 | R44: 0 | S44: 0 | T44: 0 | U44: 0 | V44: 0 | W44: 0 | X44: 0 | Y44: 0 | Z44: 0 | AA44: 0 | AB44: 0 | AC44: 0 | AD44: 0 | AE44: 0 | AF44: 0 | AG44: 0 | AH44: 0 | AI44: 0 | AJ44: 0
G45: Texas | H45: TX | I45: No | J45: 0 | K45: 0 | L45: 0 | M45: 0 | N45: 0 | O45: 0 | P45: 0 | Q45: 0 | R45: 0 | S45: 0 | T45: 0 | U45: 0 | V45: 0 | W45: 0 | X45: 0 | Y45: 0 | Z45: 0 | AA45: 0 | AB45: 0 | AC45: 0 | AD45: 0 | AE45: 0 | AF45: 0 | AG45: 0 | AH45: 0 | AI45: 0 | AJ45: 0
A46: Oregon Calcs | G46: Utah | H46: UT | I46: No | J46: 0 | K46: 0 | L46: 0 | M46: 0 | N46: 0 | O46: 0 | P46: 0 | Q46: 0 | R46: 0 | S46: 0 | T46: 0 | U46: 0 | V46: 0 | W46: 0 | X46: 0 | Y46: 0 | Z46: 0 | AA46: 0 | AB46: 0 | AC46: 0 | AD46: 0 | AE46: 0 | AF46: 0 | AG46: 0 | AH46: 0 | AI46: 0 | AJ46: 0
...

Sheet WA
A1: ear | B1: Annual carbon intensity reduction | C1: Total carbon intensity reduction (%) | D1: Carbon intensity standard - gasoline | E1: Carbon intensity standard - diesel
A2: 2025 | B2: 0.01 | C2: 0.02 | D2: 96.95 | E2: 98.11
A3: 2026 | B3: 0.05 | C3: 0.07 | D3: 92 | E3: 93.1
A4: 2027 | B4: 0.04 | C4: 0.11 | D4: 88.05 | E4: 89.1
A5: 2028-2038 | B5: 3 - 4% annually | C5: 45%* by 2038 | D5: 44.5* | E5: 45.1*

Sheet BLP
B1: 2024 | C1: 2025 | D1: 2026 | E1: 2027 | F1: 2028 | G1: 2029 | H1: 2030 | I1: 2031 | J1: 2032 | K1: 2033 | L1: 2034 | M1: 2035 | N1: 2036 | O1: 2037 | P1: 2038 | Q1: 2039 | R1: 2040 | S1: 2041 | T1: 2042 | U1: 2043 | V1: 2044 | W1: 2045 | X1: 2046 | Y1: 2047 | Z1: 2048 | AA1: 2049 | AB1: 2050
A2: BAU LCFS Perc | B2: {=_xlfn.XLOOKUP(BLP!B1, StatePolicies!$J$2:$AJ$2, _xlfn.XLOOKUP(About!$B$2, StatePolicies!$H$3:$H$52, StatePolicies!$J$3:$AJ$52))} -> 0 | C2: {=_xlfn.XLOOKUP(BLP!C1, StatePolicies!$J$2:$AJ$2, _xlfn.XLOOKUP(About!$B$2, StatePolicies!$H$3:$H$52, StatePolicies!$J$3:$AJ$52))} -> 0 | D2: {=_xlfn.XLOOKUP(BLP!D1, StatePolicies!$J$2:$AJ$2, _xlfn.XLOOKUP(About!$B$2, StatePolicies!$H$3:$H$52, StatePolicies!$J$3:$AJ$52))} -> 0 | E2: {=_xlfn.XLOOKUP(BLP!E1, StatePolicies!$J$2:$AJ$2, _xlfn.XLOOKUP(About!$B$2, StatePolicies!$H$3:$H$52, StatePolicies!$J$3:$AJ$52))} -> 0 | F2: {=_xlfn.XLOOKUP(BLP!F1, StatePolicies!$J$2:$AJ$2, _xlfn.XLOOKUP(About!$B$2, StatePolicies!$H$3:$H$52, StatePolicies!$J$3:$AJ$52))} -> 0 | G2: {=_xlfn.XLOOKUP(BLP!G1, StatePolicies!$J$2:$AJ$2, _xlfn.XLOOKUP(About!$B$2, StatePolicies!$H$3:$H$52, StatePolicies!$J$3:$AJ$52))} -> 0 | H2: {=_xlfn.XLOOKUP(BLP!H1, StatePolicies!$J$2:$AJ$2, _xlfn.XLOOKUP(About!$B$2, StatePolicies!$H$3:$H$52, StatePolicies!$J$3:$AJ$52))} -> 0 | I2: {=_xlfn.XLOOKUP(BLP!I1, StatePolicies!$J$2:$AJ$2, _xlfn.XLOOKUP(About!$B$2, StatePolicies!$H$3:$H$52, StatePolicies!$J$3:$AJ$52))} -> 0 | ... AB2: {=_xlfn.XLOOKUP(BLP!AB1, StatePolicies!$J$2:$AJ$2, _xlfn.XLOOKUP(About!$B$2, StatePolicies!$H$3:$H$52, StatePolicies!$J$3:$AJ$52))} -> 0
